Workbook

Sheet Übersicht
A1: Übersicht – Solo-Plan bis 10.000 € MRR, danach Ausbau mit Team
A2: Ergebnis vor Steuern. Im Solo-Plan ist das Ergebnis das Einkommen des Gründers (davon 35–40 % für Steuern/Sozialversicherung zurücklegen).
A4: Solo-Plan | B4: Konservativ · Hand | C4: Konservativ · auto | D4: Basis · Hand | E4: Basis · auto | F4: Optimistisch · Hand | G4: Optimistisch · auto
A5: MRR Monat 6 (Apr 27) | B5: ='Solo Konservativ'!G19 -> 5656.8524 | C5: ='Solo Konservativ auto'!G19 -> 5656.8524 | D5: ='Solo Basis'!G19 -> 8633.8798 | E5: ='Solo Basis auto'!G19 -> 9020.6248 | F5: ='Solo Optimistisch'!G19 -> 9555.9017 | G5: ='Solo Optimistisch auto'!G19 -> 12384.397
A6: MRR Monat 12 (Okt 27) | B6: ='Solo Konservativ'!M19 -> 11674.698 | C6: ='Solo Konservativ auto'!M19 -> 12034.975 | D6: ='Solo Basis'!M19 -> 12909.996 | E6: ='Solo Basis auto'!M19 -> 18519.926 | F6: ='Solo Optimistisch'!M19 -> 13119.875 | G6: ='Solo Optimistisch auto'!M19 -> 23122.317
A7: MRR Monat 24 (Okt 28) | B7: ='Solo Konservativ'!Y19 -> 14164.904 | C7: ='Solo Konservativ auto'!Y19 -> 21870.188 | D7: ='Solo Basis'!Y19 -> 14217.816 | E7: ='Solo Basis auto'!Y19 -> 26427.305 | F7: ='Solo Optimistisch'!Y19 -> 14227.379 | G7: ='Solo Optimistisch auto'!Y19 -> 26725.254
A8: Monat, in dem 10.000 € MRR erreicht werden | B8: =IF(MAX('Solo Konservativ'!B19:Y19)>=10000,COUNTIF('Solo Konservativ'!B19:Y19,"<10000")+1,"nicht in 24 Monaten") -> 10 | C8: =IF(MAX('Solo Konservativ auto'!B19:Y19)>=10000,COUNTIF('Solo Konservativ auto'!B19:Y19,"<10000")+1,"nicht in 24 Monaten") -> 10 | D8: =IF(MAX('Solo Basis'!B19:Y19)>=10000,COUNTIF('Solo Basis'!B19:Y19,"<10000")+1,"nicht in 24 Monaten") -> 8 | E8: =IF(MAX('Solo Basis auto'!B19:Y19)>=10000,COUNTIF('Solo Basis auto'!B19:Y19,"<10000")+1,"nicht in 24 Monaten") -> 7 | F8: =IF(MAX('Solo Optimistisch'!B19:Y19)>=10000,COUNTIF('Solo Optimistisch'!B19:Y19,"<10000")+1,"nicht in 24 Monaten") -> 7 | G8: =IF(MAX('Solo Optimistisch auto'!B19:Y19)>=10000,COUNTIF('Solo Optimistisch auto'!B19:Y19,"<10000")+1,"nicht in 24 Monaten") -> 5
A9: Einkommen erste 12 Monate (vor Steuern) | B9: =SUM('Solo Konservativ'!B23:M23) -> 96652.198 | C9: =SUM('Solo Konservativ auto'!B23:M23) -> 96488.323 | D9: =SUM('Solo Basis'!B23:M23) -> 125052.27 | E9: =SUM('Solo Basis auto'!B23:M23) -> 154686.39 | F9: =SUM('Solo Optimistisch'!B23:M23) -> 135249.95 | G9: =SUM('Solo Optimistisch auto'!B23:M23) -> 205965.33
A10: Abschlüsse erste 12 Monate | B10: =SUM('Solo Konservativ'!B11:M11) -> 21.434527 | C10: =SUM('Solo Konservativ auto'!B11:M11) -> 22 | D10: =SUM('Solo Basis'!B11:M11) -> 24.56373 | E10: =SUM('Solo Basis auto'!B11:M11) -> 34 | F10: =SUM('Solo Optimistisch'!B11:M11) -> 25.308961 | G10: =SUM('Solo Optimistisch auto'!B11:M11) -> 43.00575
A11: Belegte Stunden Monat 12 | B11: ='Solo Konservativ'!M25 -> 170 | C11: ='Solo Konservativ auto'!M25 -> 98.227269 | D11: ='Solo Basis'!M25 -> 170 | E11: ='Solo Basis auto'!M25 -> 150.04599 | F11: ='Solo Optimistisch'!M25 -> 170 | G11: ='Solo Optimistisch auto'!M25 -> 170
A13: Ausbau ab 10.000 € MRR (Team) | B13: Wert
A14: Team-Start | B14: ="Jul 27" -> Jul 27
A15: Umsatz erste 12 Team-Monate | B15: ='Ausbau ab 10k'!Q25 -> 821745.77
A16: Ergebnis erste 12 Team-Monate | B16: ='Ausbau ab 10k'!Q37 -> 74129.245
A17: MRR nach 12 Team-Monaten | B17: ='Ausbau ab 10k'!P23 -> 96730.19
A18: Tiefster Kassenstand im Ausbau | B18: =MIN(0,MIN('Ausbau ab 10k'!E38:P38)) -> -4565.8532
A19: Jahresumsatz-Tempo im 12. Team-Monat | B19: ='Ausbau ab 10k'!P26 -> 1798466.3
A22: MRR je Monat (Solo) | B22: Konservativ · Hand | C22: Konservativ · auto | D22: Basis · Hand | E22: Basis · auto | F22: Optimistisch · Hand | G22: Optimistisch · auto
A23: Nov 26 | B23: ='Solo Konservativ'!B19 -> 593 | C23: ='Solo Konservativ auto'!B19 -> 593 | D23: ='Solo Basis'!B19 -> 1186 | E23: ='Solo Basis auto'!B19 -> 1186 | F23: ='Solo Optimistisch'!B19 -> 1779 | G23: ='Solo Optimistisch auto'!B19 -> 1779
A24: Dez 26 | B24: ='Solo Konservativ'!C19 -> 1172.6367 | C24: ='Solo Konservativ auto'!C19 -> 1172.6367 | D24: ='Solo Basis'!C19 -> 2345.2733 | E24: ='Solo Basis auto'!C19 -> 2345.2733 | F24: ='Solo Optimistisch'!C19 -> 3517.91 | G24: ='Solo Optimistisch auto'!C19 -> 3517.91
A25: Jan 27 | B25: ='Solo Konservativ'!D19 -> 2332.227 | C25: ='Solo Konservativ auto'!D19 -> 2332.227 | D25: ='Solo Basis'!D19 -> 4071.4539 | E25: ='Solo Basis auto'!D19 -> 4071.4539 | F25: ='Solo Optimistisch'!D19 -> 5548.5749 | G25: ='Solo Optimistisch auto'!D19 -> 5810.6809
A26: Feb 27 | B26: ='Solo Konservativ'!E19 -> 3465.7167 | C26: ='Solo Konservativ auto'!E19 -> 3465.7167 | D26: ='Solo Basis'!E19 -> 5758.7966 | E26: ='Solo Basis auto'!E19 -> 5758.7966 | F26: ='Solo Optimistisch'!E19 -> 7182.4706 | G26: ='Solo Optimistisch auto'!E19 -> 8051.8766
A27: Mär 27 | B27: ='Solo Konservativ'!F19 -> 4573.7241 | C27: ='Solo Konservativ auto'!F19 -> 4573.7241 | D27: ='Solo Basis'!F19 -> 7351.8158 | E27: ='Solo Basis auto'!F19 -> 7408.2213 | F27: ='Solo Optimistisch'!F19 -> 8497.3991 | G27: ='Solo Optimistisch auto'!F19 -> 10242.718
A28: Apr 27 | B28: ='Solo Konservativ'!G19 -> 5656.8524 | C28: ='Solo Konservativ auto'!G19 -> 5656.8524 | D28: ='Solo Basis'!G19 -> 8633.8798 | E28: ='Solo Basis auto'!G19 -> 9020.6248 | F28: ='Solo Optimistisch'!G19 -> 9555.9017 | G28: ='Solo Optimistisch auto'!G19 -> 12384.397
A29: Mai 27 | B29: ='Solo Konservativ'!H19 -> 6715.6896 | C29: ='Solo Konservativ auto'!H19 -> 6715.6896 | D29: ='Solo Basis'!H19 -> 9665.9583 | E29: ='Solo Basis auto'!H19 -> 10596.882 | F29: ='Solo Optimistisch'!H19 -> 10408.252 | G29: ='Solo Optimistisch auto'!H19 -> 14478.074
A30: Jun 27 | B30: ='Solo Konservativ'!I19 -> 7849.3091 | C30: ='Solo Konservativ auto'!I19 -> 7849.3091 | D30: ='Solo Basis'!I19 -> 10666.913 | E30: ='Solo Basis auto'!I19 -> 12285.596 | F30: ='Solo Optimistisch'!I19 -> 11243.983 | G30: ='Solo Optimistisch auto'!I19 -> 16721.883
A31: Jul 27 | B31: ='Solo Konservativ'!J19 -> 8946.7021 | C31: ='Solo Konservativ auto'!J19 -> 8946.7021 | D31: ='Solo Basis'!J19 -> 11448.477 | E31: ='Solo Basis auto'!J19 -> 13920.246 | F31: ='Solo Optimistisch'!J19 -> 11896.933 | G31: ='Solo Optimistisch auto'!J19 -> 18893.79
A32: Aug 27 | B32: ='Solo Konservativ'!K19 -> 10009.243 | C32: ='Solo Konservativ auto'!K19 -> 10009.243 | D32: ='Solo Basis'!K19 -> 12059.081 | E32: ='Solo Basis auto'!K19 -> 15502.887 | F32: ='Solo Optimistisch'!K19 -> 12407.438 | G32: ='Solo Optimistisch auto'!K19 -> 20670.186
A33: Sep 27 | B33: ='Solo Konservativ'!L19 -> 10944.687 | C33: ='Solo Konservativ auto'!L19 -> 11038.247 | D33: ='Solo Basis'!L19 -> 12536.455 | E33: ='Solo Basis auto'!L19 -> 17035.487 | F33: ='Solo Optimistisch'!L19 -> 12806.924 | G33: ='Solo Optimistisch auto'!L19 -> 22050.05
A34: Okt 27 | B34: ='Solo Konservativ'!M19 -> 11674.698 | C34: ='Solo Konservativ auto'!M19 -> 12034.975 | D34: ='Solo Basis'!M19 -> 12909.996 | E34: ='Solo Basis auto'!M19 -> 18519.926 | F34: ='Solo Optimistisch'!M19 -> 13119.875 | G34: ='Solo Optimistisch auto'!M19 -> 23122.317
A35: Nov 27 | B35: ='Solo Konservativ'!N19 -> 12244.645 | C35: ='Solo Konservativ auto'!N19 -> 13000.631 | D35: ='Solo Basis'!N19 -> 13202.605 | E35: ='Solo Basis auto'!N19 -> 19958.009 | F35: ='Solo Optimistisch'!N19 -> 13365.366 | G35: ='Solo Optimistisch auto'!N19 -> 23955.972
A36: Dez 27 | B36: ='Solo Konservativ'!O19 -> 12689.874 | C36: ='Solo Konservativ auto'!O19 -> 13936.371 | D36: ='Solo Basis'!O19 -> 13432.126 | E36: ='Solo Basis auto'!O19 -> 21351.461 | F36: ='Solo Optimistisch'!O19 -> 13558.261 | G36: ='Solo Optimistisch auto'!O19 -> 24604.523
A37: Jan 28 | B37: ='Solo Konservativ'!P19 -> 13037.922 | C37: ='Solo Konservativ auto'!P19 -> 14843.3 | D37: ='Solo Basis'!P19 -> 13612.462 | E37: ='Solo Basis auto'!P19 -> 22574.762 | F37: ='Solo Optimistisch'!P19 -> 13710.138 | G37: ='Solo Optimistisch auto'!P19 -> 25109.474
A38: Feb 28 | B38: ='Solo Konservativ'!Q19 -> 13310.241 | C38: ='Solo Konservativ auto'!Q19 -> 15722.477 | D38: ='Solo Basis'!Q19 -> 13754.444 | E38: ='Solo Basis auto'!Q19 -> 23525.725 | F38: ='Solo Optimistisch'!Q19 -> 13830.022 | G38: ='Solo Optimistisch auto'!Q19 -> 25503.017
A39: Mär 28 | B39: ='Solo Konservativ'!R19 -> 13523.546 | C39: ='Solo Konservativ auto'!R19 -> 16574.918 | D39: ='Solo Basis'!R19 -> 13866.511 | E39: ='Solo Basis auto'!R19 -> 24265.42 | F39: ='Solo Optimistisch'!R19 -> 13924.942 | G39: ='Solo Optimistisch auto'!R19 -> 25810.122
A40: Apr 28 | B40: ='Solo Konservativ'!S19 -> 13690.856 | C40: ='Solo Konservativ auto'!S19 -> 17401.595 | D40: ='Solo Basis'!S19 -> 13955.239 | E40: ='Solo Basis auto'!S19 -> 24841.214 | F40: ='Solo Optimistisch'!S19 -> 14000.377 | G40: ='Solo Optimistisch auto'!S19 -> 26050.16
A41: Mai 28 | B41: ='Solo Konservativ'!T19 -> 13822.316 | C41: ='Solo Konservativ auto'!T19 -> 18203.44 | D41: ='Solo Basis'!T19 -> 14025.754 | E41: ='Solo Basis auto'!T19 -> 25289.85 | F41: ='Solo Optimistisch'!T19 -> 14060.596 | G41: ='Solo Optimistisch auto'!T19 -> 26238.153
A42: Jun 28 | B42: ='Solo Konservativ'!U19 -> 13925.83 | C42: ='Solo Konservativ auto'!U19 -> 18981.346 | D42: ='Solo Basis'!U19 -> 14082.047 | E42: ='Solo Basis auto'!U19 -> 25639.826 | F42: ='Solo Optimistisch'!U19 -> 14108.927 | G42: ='Solo Optimistisch auto'!U19 -> 26385.755
A43: Jul 28 | B43: ='Solo Konservativ'!V19 -> 14007.554 | C43: ='Solo Konservativ auto'!V19 -> 19736.169 | D43: ='Solo Basis'!V19 -> 14127.23 | E43: ='Solo Basis auto'!V19 -> 25913.25 | F43: ='Solo Optimistisch'!V19 -> 14147.962 | G43: ='Solo Optimistisch auto'!V19 -> 26502.006
A44: Aug 28 | B44: ='Solo Konservativ'!W19 -> 14072.288 | C44: ='Solo Konservativ auto'!W19 -> 20468.731 | D44: ='Solo Basis'!W19 -> 14163.729 | E44: ='Solo Basis auto'!W19 -> 26127.268 | F44: ='Solo Optimistisch'!W19 -> 14179.723 | G44: ='Solo Optimistisch auto'!W19 -> 26593.916
...

Sheet Preise
A1: Preisübersicht und Verdienst je Abschluss
A2: Blaue Werte sind Eingaben. Stunden = alles selbst gemacht, inkl. Vertrieb je Abschluss (Pflege wird mit der Website verkauft).
A3: Vertriebsstunden je Abschluss | B3: 10
A5: Produkt | B5: Einmalig | C5: Monatlich | D5: Std. einmalig | E5: Std. je Monat | F5: Umsatz 1. Jahr | G5: Stunden 1. Jahr | H5: € je Stunde | I5: Hinweis
A6: Website Start | B6: 1490 | C6: 0 | D6: 16 | E6: 0 | F6: =B6+12*C6 -> 1490 | G6: =D6+12*E6+$B$3 -> 26 | H6: =IF(G6>0,F6/G6,0) -> 57.307692 | I6: bis 5 Seiten, fertig in 2–3 Wochen
A7: Website Wachstum | B7: 2990 | C7: 0 | D7: 28 | E7: 0 | F7: =B7+12*C7 -> 2990 | G7: =D7+12*E7+$B$3 -> 38 | H7: =IF(G7>0,F7/G7,0) -> 78.684211 | I7: bis 15 Seiten, Orts- und Karriereseiten
A8: Pflege & Hosting Start | B8: 0 | C8: 49 | D8: 0 | E8: 0.25 | F8: =B8+12*C8 -> 588 | G8: =D8+12*E8+0 -> 3 | H8: =IF(G8>0,F8/G8,0) -> 196 | I8: 12 Monate Laufzeit
A9: Pflege & Hosting Wachstum | B9: 0 | C9: 89 | D9: 0 | E9: 0.5 | F9: =B9+12*C9 -> 1068 | G9: =D9+12*E9+0 -> 6 | H9: =IF(G9>0,F9/G9,0) -> 178 | I9: 12 Monate Laufzeit, inkl. 1 h Änderungen
A10: SEO Lokal | B10: 0 | C10: 390 | D10: 4 | E10: 5 | F10: =B10+12*C10 -> 4680 | G10: =D10+12*E10+$B$3 -> 74 | H10: =IF(G10>0,F10/G10,0) -> 63.243243 | I10: 6 Monate Mindestlaufzeit
A11: SEO Plus | B11: 0 | C11: 690 | D11: 6 | E11: 8 | F11: =B11+12*C11 -> 8280 | G11: =D11+12*E11+$B$3 -> 112 | H11: =IF(G11>0,F11/G11,0) -> 73.928571 | I11: 6 Monate Mindestlaufzeit
A12: Google-Ads-Betreuung | B12: 390 | C12: 290 | D12: 4 | E12: 2.5 | F12: =B12+12*C12 -> 3870 | G12: =D12+12*E12+$B$3 -> 44 | H12: =IF(G12>0,F12/G12,0) -> 87.954545 | I12: zzgl. Werbebudget, monatlich kündbar
A13: Recruiting-Paket | B13: 1490 | C13: 790 | D13: 10 | E13: 7 | F13: =B13+12*C13 -> 10970 | G13: =D13+12*E13+$B$3 -> 104 | H13: =IF(G13>0,F13/G13,0) -> 105.48077 | I13: zzgl. Werbebudget, 3 Monate Mindestlaufzeit
A14: Wachstumsprogramm | B14: 1490 | C14: 1190 | D14: 28 | E14: 13 | F14: =B14+12*C14 -> 15770 | G14: =D14+12*E14+$B$3 -> 194 | H14: =IF(G14>0,F14/G14,0) -> 81.28866 | I14: 12 Monate, Website + SEO Plus + Ads inklusive
A16: Faustregel netto: Vom Gewinn 35–40 % für Einkommensteuer und Sozialversicherung zurücklegen (Steuerberater fragen).

Sheet Annahmen
A1: Annahmen Solo-Plan (Gründer macht Vertrieb und Umsetzung allein)
A2: Blaue Zahlen sind Eingaben. Gelb = wichtigste Hebel. Monat 1 = November 2026.
A4: Annahme | B4: Wert
A5: Ø Website-Auftrag (einmalig) | B5: 2200
A6: Ø Pflege & Hosting / Monat | B6: 69
A7: Wachstumsprogramm / Monat | B7: 1190
A8: Programm-Einrichtung (inkl. Website) | B8: 1490
A9: Ø SEO / Monat | B9: 520
A10: Recruiting-Paket / Monat | B10: 790
A11: Recruiting-Einrichtung | B11: 1490
A12: Anteil Abschlüsse: Website (+ Pflege) | B12: 0.25
A13: Anteil Abschlüsse: Wachstumsprogramm | B13: 0.25
A14: Anteil Abschlüsse: SEO | B14: 0.25
A15: Anteil Abschlüsse: Recruiting | B15: 0.25
A16: Recruiting wird verkauft ab Monat (8 = Jun 27) | B16: 8
... A43: Eigenes Marketing / Monat | B43: 150
A45: Std. je neuem Abschluss (Ø von Hand, alle Produkte, inkl. Vertrieb) | B45: =Annahmen!$B$12*(Annahmen!$B$21+Annahmen!$B$25+Annahmen!$B$29)+Annahmen!$B$13*(Annahmen!$B$22+Annahmen!$B$26+Annahmen!$B$29)+Annahmen!$B$14*(Annahmen!$B$23+Annahmen!$B$27+Annahmen!$B$29)+Annahmen!$B$15*(Annahmen!$B$24+Annahmen!$B$28+Annahmen!$B$29) -> 34.5625
A47: Abschluss-Ziel (Vertriebstempo) | B47: Konservativ | C47: Basis | D47: Optimistisch
A48: Abschlüsse / Monat, Monat 1–2 | B48: 1 | C48: 2 | D48: 3
A49: Abschlüsse / Monat, ab Monat 3 | B49: 2 | C49: 3 | D49: 4

Sheet Solo Konservativ
A1: Solo-Plan · Szenario Konservativ · von Hand (24 Monate ab Nov 2026)
A2: Abschlüsse = Minimum aus Vertriebstempo und freien Stunden. Kundenzahlen sind Erwartungswerte.
A4: Monat | B4: Nov 26 | C4: Dez 26 | D4: Jan 27 | E4: Feb 27 | F4: Mär 27 | G4: Apr 27 | H4: Mai 27 | I4: Jun 27 | J4: Jul 27 | K4: Aug 27 | L4: Sep 27 | M4: Okt 27 | N4: Nov 27 | O4: Dez 27 | P4: Jan 28 | Q4: Feb 28 | R4: Mär 28 | S4: Apr 28 | T4: Mai 28 | U4: Jun 28 | V4: Jul 28 | W4: Aug 28 | X4: Sep 28 | Y4: Okt 28
A5: Abschluss-Ziel (Vertrieb) | B5: =Annahmen!$B$48 -> 1 | C5: =Annahmen!$B$48 -> 1 | D5: =Annahmen!$B$49 -> 2 | E5: =Annahmen!$B$49 -> 2 | F5: =Annahmen!$B$49 -> 2 | G5: =Annahmen!$B$49 -> 2 | H5: =Annahmen!$B$49 -> 2 | I5: =Annahmen!$B$49 -> 2 | J5: =Annahmen!$B$49 -> 2 | K5: =Annahmen!$B$49 -> 2 | ... Y5: =Annahmen!$B$49 -> 2
A6: Recruiting im Verkauf (1 = ja) | B6: =IF(1>=Annahmen!$B$16,1,0) -> 0 | C6: =IF(2>=Annahmen!$B$16,1,0) -> 0 | D6: =IF(3>=Annahmen!$B$16,1,0) -> 0 | E6: =IF(4>=Annahmen!$B$16,1,0) -> 0 | F6: =IF(5>=Annahmen!$B$16,1,0) -> 0 | G6: =IF(6>=Annahmen!$B$16,1,0) -> 0 | H6: =IF(7>=Annahmen!$B$16,1,0) -> 0 | I6: =IF(8>=Annahmen!$B$16,1,0) -> 1 | J6: =IF(9>=Annahmen!$B$16,1,0) -> 1 | K6: =IF(10>=Annahmen!$B$16,1,0) -> 1 | L6: =IF(11>=Annahmen!$B$16,1,0) -> 1 | M6: =IF(12>=Annahmen!$B$16,1,0) -> 1 | N6: =IF(13>=Annahmen!$B$16,1,0) -> 1 | O6: =IF(14>=Annahmen!$B$16,1,0) -> 1 | P6: =IF(15>=Annahmen!$B$16,1,0) -> 1 | Q6: =IF(16>=Annahmen!$B$16,1,0) -> 1 | R6: =IF(17>=Annahmen!$B$16,1,0) -> 1 | S6: =IF(18>=Annahmen!$B$16,1,0) -> 1 | T6: =IF(19>=Annahmen!$B$16,1,0) -> 1 | U6: =IF(20>=Annahmen!$B$16,1,0) -> 1 | V6: =IF(21>=Annahmen!$B$16,1,0) -> 1 | W6: =IF(22>=Annahmen!$B$16,1,0) -> 1 | X6: =IF(23>=Annahmen!$B$16,1,0) -> 1 | Y6: =IF(24>=Annahmen!$B$16,1,0) -> 1
A7: Automatisierung aktiv (1 = ja) | B7: =0 -> 0 | C7: =0 -> 0 | D7: =0 -> 0 | E7: =0 -> 0 | F7: =0 -> 0 | G7: =0 -> 0 | H7: =0 -> 0 | I7: =0 -> 0 | ... Y7: =0 -> 0
A8: Std. je neuem Abschluss | B8: =Annahmen!$B$12/(1-Annahmen!$B$15*(1-B6))*((Annahmen!$B$21+B7*(Annahmen!$B$30-Annahmen!$B$21))+(Annahmen!$B$25+B7*(Annahmen!$B$34-Annahmen!$B$25))+(Annahmen!$B$29+B7*(Annahmen!$B$38-Annahmen!$B$29)))+Annahmen!$B$13/(1-Annahmen!$B$15*(1-B6))*((Annahmen!$B$22+B7*(Annahmen!$B$31-Annahmen!$B$22))+(Annahmen!$B$26+B7*(Annahmen!$B$35-Annahmen!$B$26))+(Annahmen!$B$29+B7*(Annahmen!$B$38-Annahmen!$B$29)))+Annahmen!$B$14/(1-Annahmen!$B$15*(1-B6))*((Annahmen!$B$23+B7*(Annahmen!$B$32-Annahmen!$B$23))+(Annahmen!$B$27+B7*(Annahmen!$B$36-Annahmen!$B$27))+(Annahmen!$B$29+B7*(Annahmen!$B$38-Annahmen!$B$29)))+Annahmen!$B$15*B6*((Annahmen!$B$24+B7*(Annahmen!$B$33-Annahmen!$B$24))+(Annahmen!$B$28+B7*(Annahmen!$B$37-Annahmen!$B$28))+(Annahmen!$B$29+B7*(Annahmen!$B$38-Annahmen!$B$29))) -> 37.083333 | C8: =Annahmen!$B$12/(1-Annahmen!$B$15*(1-C6))*((Annahmen!$B$21+C7*(Annahmen!$B$30-Annahmen!$B$21))+(Annahmen!$B$25+C7*(Annahmen!$B$34-Annahmen!$B$25))+(Annahmen!$B$29+C7*(Annahmen!$B$38-Annahmen!$B$29)))+Annahmen!$B$13/(1-Annahmen!$B$15*(1-C6))*((Annahmen!$B$22+C7*(Annahmen!$B$31-Annahmen!$B$22))+(Annahmen!$B$26+C7*(Annahmen!$B$35-Annahmen!$B$26))+(Annahmen!$B$29+C7*(Annahmen!$B$38-Annahmen!$B$29)))+Annahmen!$B$14/(1-Annahmen!$B$15*(1-C6))*((Annahmen!$B$23+C7*(Annahmen!$B$32-Annahmen!$B$23))+(Annahmen!$B$27+C7*(Annahmen!$B$36-Annahmen!$B$27))+(Annahmen!$B$29+C7*(Annahmen!$B$38-Annahmen!$B$29)))+Annahmen!$B$15*C6*((Annahmen!$B$24+C7*(Annahmen!$B$33-Annahmen!$B$24))+(Annahmen!$B$28+C7*(Annahmen!$B$37-Annahmen!$B$28))+(Annahmen!$B$29+C7*(Annahmen!$B$38-Annahmen!$B$29))) -> 37.083333 | D8: =Annahmen!$B$12/(1-Annahmen!$B$15*(1-D6))*((Annahmen!$B$21+D7*(Annahmen!$B$30-Annahmen!$B$21))+(Annahmen!$B$25+D7*(Annahmen!$B$34-Annahmen!$B$25))+(Annahmen!$B$29+D7*(Annahmen!$B$38-Annahmen!$B$29)))+Annahmen!$B$13/(1-Annahmen!$B$15*(1-D6))*((Annahmen!$B$22+D7*(Annahmen!$B$31-Annahmen!$B$22))+(Annahmen!$B$26+D7*(Annahmen!$B$35-Annahmen!$B$26))+(Annahmen!$B$29+D7*(Annahmen!$B$38-Annahmen!$B$29)))+Annahmen!$B$14/(1-Annahmen!$B$15*(1-D6))*((Annahmen!$B$23+D7*(Annahmen!$B$32-Annahmen!$B$23))+(Annahmen!$B$27+D7*(Annahmen!$B$36-Annahmen!$B$27))+(Annahmen!$B$29+D7*(Annahmen!$B$38-Annahmen!$B$29)))+Annahmen!$B$15*D6*((Annahmen!$B$24+D7*(Annahmen!$B$33-Annahmen!$B$24))+(Annahmen!$B$28+D7*(Annahmen!$B$37-Annahmen!$B$28))+(Annahmen!$B$29+D7*(Annahmen!$B$38-Annahmen!$B$29))) -> 37.083333 | E8: =Annahmen!$B$12/(1-Annahmen!$B$15*(1-E6))*((Annahmen!$B$21+E7*(Annahmen!$B$30-Annahmen!$B$21))+(Annahmen!$B$25+E7*(Annahmen!$B$34-Annahmen!$B$25))+(Annahmen!$B$29+E7*(Annahmen!$B$38-Annahmen!$B$29)))+Annahmen!$B$13/(1-Annahmen!$B$15*(1-E6))*((Annahmen!$B$22+E7*(Annahmen!$B$31-Annahmen!$B$22))+(Annahmen!$B$26+E7*(Annahmen!$B$35-Annahmen!$B$26))+(Annahmen!$B$29+E7*(Annahmen!$B$38-Annahmen!$B$29)))+Annahmen!$B$14/(1-Annahmen!$B$15*(1-E6))*((Annahmen!$B$23+E7*(Annahmen!$B$32-Annahmen!$B$23))+(Annahmen!$B$27+E7*(Annahmen!$B$36-Annahmen!$B$27))+(Annahmen!$B$29+E7*(Annahmen!$B$38-Annahmen!$B$29)))+Annahmen!$B$15*E6*((Annahmen!$B$24+E7*(Annahmen!$B$33-Annahmen!$B$24))+(Annahmen!$B$28+E7*(Annahmen!$B$37-Annahmen!$B$28))+(Annahmen!$B$29+E7*(Annahmen!$B$38-Annahmen!$B$29))) -> 37.083333 | F8: =Annahmen!$B$12/(1-Annahmen!$B$15*(1-F6))*((Annahmen!$B$21+F7*(Annahmen!$B$30-Annahmen!$B$21))+(Annahmen!$B$25+F7*(Annahmen!$B$34-Annahmen!$B$25))+(Annahmen!$B$29+F7*(Annahmen!$B$38-Annahmen!$B$29)))+Annahmen!$B$13/(1-Annahmen!$B$15*(1-F6))*((Annahmen!$B$22+F7*(Annahmen!$B$31-Annahmen!$B$22))+(Annahmen!$B$26+F7*(Annahmen!$B$35-Annahmen!$B$26))+(Annahmen!$B$29+F7*(Annahmen!$B$38-Annahmen!$B$29)))+Annahmen!$B$14/(1-Annahmen!$B$15*(1-F6))*((Annahmen!$B$23+F7*(Annahmen!$B$32-Annahmen!$B$23))+(Annahmen!$B$27+F7*(Annahmen!$B$36-Annahmen!$B$27))+(Annahmen!$B$29+F7*(Annahmen!$B$38-Annahmen!$B$29)))+Annahmen!$B$15*F6*((Annahmen!$B$24+F7*(Annahmen!$B$33-Annahmen!$B$24))+(Annahmen!$B$28+F7*(Annahmen!$B$37-Annahmen!$B$28))+(Annahmen!$B$29+F7*(Annahmen!$B$38-Annahmen!$B$29))) -> 37.083333 | G8: =Annahmen!$B$12/(1-Annahmen!$B$15*(1-G6))*((Annahmen!$B$21+G7*(Annahmen!$B$30-Annahmen!$B$21))+(Annahmen!$B$25+G7*(Annahmen!$B$34-Annahmen!$B$25))+(Annahmen!$B$29+G7*(Annahmen!$B$38-Annahmen!$B$29)))+Annahmen!$B$13/(1-Annahmen!$B$15*(1-G6))*((Annahmen!$B$22+G7*(Annahmen!$B$31-Annahmen!$B$22))+(Annahmen!$B$26+G7*(Annahmen!$B$35-Annahmen!$B$26))+(Annahmen!$B$29+G7*(Annahmen!$B$38-Annahmen!$B$29)))+Annahmen!$B$14/(1-Annahmen!$B$15*(1-G6))*((Annahmen!$B$23+G7*(Annahmen!$B$32-Annahmen!$B$23))+(Annahmen!$B$27+G7*(Annahmen!$B$36-Annahmen!$B$27))+(Annahmen!$B$29+G7*(Annahmen!$B$38-Annahmen!$B$29)))+Annahmen!$B$15*G6*((Annahmen!$B$24+G7*(Annahmen!$B$33-Annahmen!$B$24))+(Annahmen!$B$28+G7*(Annahmen!$B$37-Annahmen!$B$28))+(Annahmen!$B$29+G7*(Annahmen!$B$38-Annahmen!$B$29))) -> 37.083333 | H8: =Annahmen!$B$12/(1-Annahmen!$B$15*(1-H6))*((Annahmen!$B$21+H7*(Annahmen!$B$30-Annahmen!$B$21))+(Annahmen!$B$25+H7*(Annahmen!$B$34-Annahmen!$B$25))+(Annahmen!$B$29+H7*(Annahmen!$B$38-Annahmen!$B$29)))+Annahmen!$B$13/(1-Annahmen!$B$15*(1-H6))*((Annahmen!$B$22+H7*(Annahmen!$B$31-Annahmen!$B$22))+(Annahmen!$B$26+H7*(Annahmen!$B$35-Annahmen!$B$26))+(Annahmen!$B$29+H7*(Annahmen!$B$38-Annahmen!$B$29)))+Annahmen!$B$14/(1-Annahmen!$B$15*(1-H6))*((Annahmen!$B$23+H7*(Annahmen!$B$32-Annahmen!$B$23))+(Annahmen!$B$27+H7*(Annahmen!$B$36-Annahmen!$B$27))+(Annahmen!$B$29+H7*(Annahmen!$B$38-Annahmen!$B$29)))+Annahmen!$B$15*H6*((Annahmen!$B$24+H7*(Annahmen!$B$33-Annahmen!$B$24))+(Annahmen!$B$28+H7*(Annahmen!$B$37-Annahmen!$B$28))+(Annahmen!$B$29+H7*(Annahmen!$B$38-Annahmen!$B$29))) -> 37.083333 | I8: =Annahmen!$B$12/(1-Annahmen!$B$15*(1-I6))*((Annahmen!$B$21+I7*(Annahmen!$B$30-Annahmen!$B$21))+(Annahmen!$B$25+I7*(Annahmen!$B$34-Annahmen!$B$25))+(Annahmen!$B$29+I7*(Annahmen!$B$38-Annahmen!$B$29)))+Annahmen!$B$13/(1-Annahmen!$B$15*(1-I6))*((Annahmen!$B$22+I7*(Annahmen!$B$31-Annahmen!$B$22))+(Annahmen!$B$26+I7*(Annahmen!$B$35-Annahmen!$B$26))+(Annahmen!$B$29+I7*(Annahmen!$B$38-Annahmen!$B$29)))+Annahmen!$B$14/(1-Annahmen!$B$15*(1-I6))*((Annahmen!$B$23+I7*(Annahmen!$B$32-Annahmen!$B$23))+(Annahmen!$B$27+I7*(Annahmen!$B$36-Annahmen!$B$27))+(Annahmen!$B$29+I7*(Annahmen!$B$38-Annahmen!$B$29)))+Annahmen!$B$15*I6*((Annahmen!$B$24+I7*(Annahmen!$B$33-Annahmen!$B$24))+(Annahmen!$B$28+I7*(Annahmen!$B$37-Annahmen!$B$28))+(Annahmen!$B$29+I7*(Annahmen!$B$38-Annahmen!$B$29))) -> 34.5625 | ... Y8: =Annahmen!$B$12/(1-Annahmen!$B$15*(1-Y6))*((Annahmen!$B$21+Y7*(Annahmen!$B$30-Annahmen!$B$21))+(Annahmen!$B$25+Y7*(Annahmen!$B$34-Annahmen!$B$25))+(Annahmen!$B$29+Y7*(Annahmen!$B$38-Annahmen!$B$29)))+Annahmen!$B$13/(1-Annahmen!$B$15*(1-Y6))*((Annahmen!$B$22+Y7*(Annahmen!$B$31-Annahmen!$B$22))+(Annahmen!$B$26+Y7*(Annahmen!$B$35-Annahmen!$B$26))+(Annahmen!$B$29+Y7*(Annahmen!$B$38-Annahmen!$B$29)))+Annahmen!$B$14/(1-Annahmen!$B$15*(1-Y6))*((Annahmen!$B$23+Y7*(Annahmen!$B$32-Annahmen!$B$23))+(Annahmen!$B$27+Y7*(Annahmen!$B$36-Annahmen!$B$27))+(Annahmen!$B$29+Y7*(Annahmen!$B$38-Annahmen!$B$29)))+Annahmen!$B$15*Y6*((Annahmen!$B$24+Y7*(Annahmen!$B$33-Annahmen!$B$24))+(Annahmen!$B$28+Y7*(Annahmen!$B$37-Annahmen!$B$28))+(Annahmen!$B$29+Y7*(Annahmen!$B$38-Annahmen!$B$29))) -> 34.5625
A9: Laufende Stunden (Bestand) | B9: =0*(Annahmen!$B$25+B7*(Annahmen!$B$34-Annahmen!$B$25))+0*(Annahmen!$B$26+B7*(Annahmen!$B$35-Annahmen!$B$26))+0*(Annahmen!$B$27+B7*(Annahmen!$B$36-Annahmen!$B$27))+0*(Annahmen!$B$28+B7*(Annahmen!$B$37-Annahmen!$B$28)) -> 0 | C9: =B14*(Annahmen!$B$25+C7*(Annahmen!$B$34-Annahmen!$B$25))+B15*(Annahmen!$B$26+C7*(Annahmen!$B$35-Annahmen!$B$26))+B16*(Annahmen!$B$27+C7*(Annahmen!$B$36-Annahmen!$B$27))+B17*(Annahmen!$B$28+C7*(Annahmen!$B$37-Annahmen!$B$28)) -> 6.4166667 | D9: =C14*(Annahmen!$B$25+D7*(Annahmen!$B$34-Annahmen!$B$25))+C15*(Annahmen!$B$26+D7*(Annahmen!$B$35-Annahmen!$B$26))+C16*(Annahmen!$B$27+D7*(Annahmen!$B$36-Annahmen!$B$27))+C17*(Annahmen!$B$28+D7*(Annahmen!$B$37-Annahmen!$B$28)) -> 12.685833 | E9: =D14*(Annahmen!$B$25+E7*(Annahmen!$B$34-Annahmen!$B$25))+D15*(Annahmen!$B$26+E7*(Annahmen!$B$35-Annahmen!$B$26))+D16*(Annahmen!$B$27+E7*(Annahmen!$B$36-Annahmen!$B$27))+D17*(Annahmen!$B$28+E7*(Annahmen!$B$37-Annahmen!$B$28)) -> 25.227708 | F9: =E14*(Annahmen!$B$25+F7*(Annahmen!$B$34-Annahmen!$B$25))+E15*(Annahmen!$B$26+F7*(Annahmen!$B$35-Annahmen!$B$26))+E16*(Annahmen!$B$27+F7*(Annahmen!$B$36-Annahmen!$B$27))+E17*(Annahmen!$B$28+F7*(Annahmen!$B$37-Annahmen!$B$28)) -> 37.481578 | G9: =F14*(Annahmen!$B$25+G7*(Annahmen!$B$34-Annahmen!$B$25))+F15*(Annahmen!$B$26+G7*(Annahmen!$B$35-Annahmen!$B$26))+F16*(Annahmen!$B$27+G7*(Annahmen!$B$36-Annahmen!$B$27))+F17*(Annahmen!$B$28+G7*(Annahmen!$B$37-Annahmen!$B$28)) -> 49.45435 | H9: =G14*(Annahmen!$B$25+H7*(Annahmen!$B$34-Annahmen!$B$25))+G15*(Annahmen!$B$26+H7*(Annahmen!$B$35-Annahmen!$B$26))+G16*(Annahmen!$B$27+H7*(Annahmen!$B$36-Annahmen!$B$27))+G17*(Annahmen!$B$28+H7*(Annahmen!$B$37-Annahmen!$B$28)) -> 61.15276 | I9: =H14*(Annahmen!$B$25+I7*(Annahmen!$B$34-Annahmen!$B$25))+H15*(Annahmen!$B$26+I7*(Annahmen!$B$35-Annahmen!$B$26))+H16*(Annahmen!$B$27+I7*(Annahmen!$B$36-Annahmen!$B$27))+H17*(Annahmen!$B$28+I7*(Annahmen!$B$37-Annahmen!$B$28)) -> 72.583375 | J9: =I14*(Annahmen!$B$25+J7*(Annahmen!$B$34-Annahmen!$B$25))+I15*(Annahmen!$B$26+J7*(Annahmen!$B$35-Annahmen!$B$26))+I16*(Annahmen!$B$27+J7*(Annahmen!$B$36-Annahmen!$B$27))+I17*(Annahmen!$B$28+J7*(Annahmen!$B$37-Annahmen!$B$28)) -> 84.044265 | ... Y9: =X14*(Annahmen!$B$25+Y7*(Annahmen!$B$34-Annahmen!$B$25))+X15*(Annahmen!$B$26+Y7*(Annahmen!$B$35-Annahmen!$B$26))+X16*(Annahmen!$B$27+Y7*(Annahmen!$B$36-Annahmen!$B$27))+X17*(Annahmen!$B$28+Y7*(Annahmen!$B$37-Annahmen!$B$28)) -> 147.27621
A10: Möglich nach Stunden | B10: =MAX(0,(Annahmen!$B$41-B9)/B8) -> 4.5842697 | C10: =MAX(0,(Annahmen!$B$41-C9)/C8) -> 4.411236 | D10: =MAX(0,(Annahmen!$B$41-D9)/D8) -> 4.2421798 | E10: =MAX(0,(Annahmen!$B$41-E9)/E8) -> 3.9039719 | F10: =MAX(0,(Annahmen!$B$41-F9)/F8) -> 3.5735305 | G10: =MAX(0,(Annahmen!$B$41-G9)/G8) -> 3.2506692 | H10: =MAX(0,(Annahmen!$B$41-H9)/H8) -> 2.9352065 | I10: =MAX(0,(Annahmen!$B$41-I9)/I8) -> 2.8185642 | ... Y10: =MAX(0,(Annahmen!$B$41-Y9)/Y8) -> 0.65746958
A11: Abschlüsse | B11: =MIN(B5,B10) -> 1 | C11: =MIN(C5,C10) -> 1 | D11: =MIN(D5,D10) -> 2 | E11: =MIN(E5,E10) -> 2 | F11: =MIN(F5,F10) -> 2 | G11: =MIN(G5,G10) -> 2 | H11: =MIN(H5,H10) -> 2 | I11: =MIN(I5,I10) -> 2 | ... Y11: =MIN(Y5,Y10) -> 0.65746958
A12: Abschlüsse kumuliert | B12: =0+B11 -> 1 | C12: =B12+C11 -> 2 | D12: =C12+D11 -> 4 | E12: =D12+E11 -> 6 | F12: =E12+F11 -> 8 | G12: =F12+G11 -> 10 | H12: =G12+H11 -> 12 | I12: =H12+I11 -> 14 | J12: =I12+J11 -> 16 | ... Y12: =X12+Y11 -> 32.010516
A14: Aktive Pflege-Kunden | B14: =0*(1-Annahmen!$B$17)+B11*Annahmen!$B$12/(1-Annahmen!$B$15*(1-B6)) -> 0.33333333 | C14: =B14*(1-Annahmen!$B$17)+C11*Annahmen!$B$12/(1-Annahmen!$B$15*(1-C6)) -> 0.66333333 | D14: =C14*(1-Annahmen!$B$17)+D11*Annahmen!$B$12/(1-Annahmen!$B$15*(1-D6)) -> 1.3233667 | E14: =D14*(1-Annahmen!$B$17)+E11*Annahmen!$B$12/(1-Annahmen!$B$15*(1-E6)) -> 1.9767997 | F14: =E14*(1-Annahmen!$B$17)+F11*Annahmen!$B$12/(1-Annahmen!$B$15*(1-F6)) -> 2.6236983 | G14: =F14*(1-Annahmen!$B$17)+G11*Annahmen!$B$12/(1-Annahmen!$B$15*(1-G6)) -> 3.264128 | H14: =G14*(1-Annahmen!$B$17)+H11*Annahmen!$B$12/(1-Annahmen!$B$15*(1-H6)) -> 3.8981534 | I14: =H14*(1-Annahmen!$B$17)+I11*Annahmen!$B$12/(1-Annahmen!$B$15*(1-I6)) -> 4.3591719 | J14: =I14*(1-Annahmen!$B$17)+J11*Annahmen!$B$12/(1-Annahmen!$B$15*(1-J6)) -> 4.8155802 | ... Y14: =X14*(1-Annahmen!$B$17)+Y11*Annahmen!$B$12/(1-Annahmen!$B$15*(1-Y6)) -> 7.8162486
A15: Aktive Programm-Kunden | B15: =0*(1-Annahmen!$B$18)+B11*Annahmen!$B$13/(1-Annahmen!$B$15*(1-B6)) -> 0.33333333 | C15: =B15*(1-Annahmen!$B$18)+C11*Annahmen!$B$13/(1-Annahmen!$B$15*(1-C6)) -> 0.66 | D15: =C15*(1-Annahmen!$B$18)+D11*Annahmen!$B$13/(1-Annahmen!$B$15*(1-D6)) -> 1.3134667 | E15: =D15*(1-Annahmen!$B$18)+E11*Annahmen!$B$13/(1-Annahmen!$B$15*(1-E6)) -> 1.953864 | F15: =E15*(1-Annahmen!$B$18)+F11*Annahmen!$B$13/(1-Annahmen!$B$15*(1-F6)) -> 2.5814534 | G15: =F15*(1-Annahmen!$B$18)+G11*Annahmen!$B$13/(1-Annahmen!$B$15*(1-G6)) -> 3.196491 | H15: =G15*(1-Annahmen!$B$18)+H11*Annahmen!$B$13/(1-Annahmen!$B$15*(1-H6)) -> 3.7992278 | I15: =H15*(1-Annahmen!$B$18)+I11*Annahmen!$B$13/(1-Annahmen!$B$15*(1-I6)) -> 4.2232433 | J15: =I15*(1-Annahmen!$B$18)+J11*Annahmen!$B$13/(1-Annahmen!$B$15*(1-J6)) -> 4.6387784 | ... Y15: =X15*(1-Annahmen!$B$18)+Y11*Annahmen!$B$13/(1-Annahmen!$B$15*(1-Y6)) -> 6.8030649
A16: Aktive SEO-Kunden | B16: =0*(1-Annahmen!$B$19)+B11*Annahmen!$B$14/(1-Annahmen!$B$15*(1-B6)) -> 0.33333333 | C16: =B16*(1-Annahmen!$B$19)+C11*Annahmen!$B$14/(1-Annahmen!$B$15*(1-C6)) -> 0.65666667 | D16: =C16*(1-Annahmen!$B$19)+D11*Annahmen!$B$14/(1-Annahmen!$B$15*(1-D6)) -> 1.3036333 | E16: =D16*(1-Annahmen!$B$19)+E11*Annahmen!$B$14/(1-Annahmen!$B$15*(1-E6)) -> 1.931191 | F16: =E16*(1-Annahmen!$B$19)+F11*Annahmen!$B$14/(1-Annahmen!$B$15*(1-F6)) -> 2.5399219 | G16: =F16*(1-Annahmen!$B$19)+G11*Annahmen!$B$14/(1-Annahmen!$B$15*(1-G6)) -> 3.1303909 | H16: =G16*(1-Annahmen!$B$19)+H11*Annahmen!$B$14/(1-Annahmen!$B$15*(1-H6)) -> 3.7031459 | I16: =H16*(1-Annahmen!$B$19)+I11*Annahmen!$B$14/(1-Annahmen!$B$15*(1-I6)) -> 4.0920515 | J16: =I16*(1-Annahmen!$B$19)+J11*Annahmen!$B$14/(1-Annahmen!$B$15*(1-J6)) -> 4.46929 | ... Y16: =X16*(1-Annahmen!$B$19)+Y11*Annahmen!$B$14/(1-Annahmen!$B$15*(1-Y6)) -> 5.9372817
A17: Aktive Recruiting-Kunden | B17: =0*(1-Annahmen!$B$20)+B11*Annahmen!$B$15*B6 -> 0 | C17: =B17*(1-Annahmen!$B$20)+C11*Annahmen!$B$15*C6 -> 0 | D17: =C17*(1-Annahmen!$B$20)+D11*Annahmen!$B$15*D6 -> 0 | E17: =D17*(1-Annahmen!$B$20)+E11*Annahmen!$B$15*E6 -> 0 | F17: =E17*(1-Annahmen!$B$20)+F11*Annahmen!$B$15*F6 -> 0 | G17: =F17*(1-Annahmen!$B$20)+G11*Annahmen!$B$15*G6 -> 0 | H17: =G17*(1-Annahmen!$B$20)+H11*Annahmen!$B$15*H6 -> 0 | I17: =H17*(1-Annahmen!$B$20)+I11*Annahmen!$B$15*I6 -> 0.5 | J17: =I17*(1-Annahmen!$B$20)+J11*Annahmen!$B$15*J6 -> 0.975 | ... Y17: =X17*(1-Annahmen!$B$20)+Y11*Annahmen!$B$15*Y6 -> 3.0918346
A19: MRR | B19: =B14*Annahmen!$B$6+B15*Annahmen!$B$7+B16*Annahmen!$B$9+B17*Annahmen!$B$10 -> 593 | C19: =C14*Annahmen!$B$6+C15*Annahmen!$B$7+C16*Annahmen!$B$9+C17*Annahmen!$B$10 -> 1172.6367 | D19: =D14*Annahmen!$B$6+D15*Annahmen!$B$7+D16*Annahmen!$B$9+D17*Annahmen!$B$10 -> 2332.227 | E19: =E14*Annahmen!$B$6+E15*Annahmen!$B$7+E16*Annahmen!$B$9+E17*Annahmen!$B$10 -> 3465.7167 | F19: =F14*Annahmen!$B$6+F15*Annahmen!$B$7+F16*Annahmen!$B$9+F17*Annahmen!$B$10 -> 4573.7241 | G19: =G14*Annahmen!$B$6+G15*Annahmen!$B$7+G16*Annahmen!$B$9+G17*Annahmen!$B$10 -> 5656.8524 | H19: =H14*Annahmen!$B$6+H15*Annahmen!$B$7+H16*Annahmen!$B$9+H17*Annahmen!$B$10 -> 6715.6896 | I19: =I14*Annahmen!$B$6+I15*Annahmen!$B$7+I16*Annahmen!$B$9+I17*Annahmen!$B$10 -> 7849.3091 | ... Y19: =Y14*Annahmen!$B$6+Y15*Annahmen!$B$7+Y16*Annahmen!$B$9+Y17*Annahmen!$B$10 -> 14164.904
A20: Einmalumsatz | B20: =B11*(Annahmen!$B$12/(1-Annahmen!$B$15*(1-B6))*Annahmen!$B$5+Annahmen!$B$13/(1-Annahmen!$B$15*(1-B6))*Annahmen!$B$8+Annahmen!$B$15*B6*Annahmen!$B$11) -> 1230 | C20: =C11*(Annahmen!$B$12/(1-Annahmen!$B$15*(1-C6))*Annahmen!$B$5+Annahmen!$B$13/(1-Annahmen!$B$15*(1-C6))*Annahmen!$B$8+Annahmen!$B$15*C6*Annahmen!$B$11) -> 1230 | D20: =D11*(Annahmen!$B$12/(1-Annahmen!$B$15*(1-D6))*Annahmen!$B$5+Annahmen!$B$13/(1-Annahmen!$B$15*(1-D6))*Annahmen!$B$8+Annahmen!$B$15*D6*Annahmen!$B$11) -> 2460 | E20: =E11*(Annahmen!$B$12/(1-Annahmen!$B$15*(1-E6))*Annahmen!$B$5+Annahmen!$B$13/(1-Annahmen!$B$15*(1-E6))*Annahmen!$B$8+Annahmen!$B$15*E6*Annahmen!$B$11) -> 2460 | F20: =F11*(Annahmen!$B$12/(1-Annahmen!$B$15*(1-F6))*Annahmen!$B$5+Annahmen!$B$13/(1-Annahmen!$B$15*(1-F6))*Annahmen!$B$8+Annahmen!$B$15*F6*Annahmen!$B$11) -> 2460 | G20: =G11*(Annahmen!$B$12/(1-Annahmen!$B$15*(1-G6))*Annahmen!$B$5+Annahmen!$B$13/(1-Annahmen!$B$15*(1-G6))*Annahmen!$B$8+Annahmen!$B$15*G6*Annahmen!$B$11) -> 2460 | H20: =H11*(Annahmen!$B$12/(1-Annahmen!$B$15*(1-H6))*Annahmen!$B$5+Annahmen!$B$13/(1-Annahmen!$B$15*(1-H6))*Annahmen!$B$8+Annahmen!$B$15*H6*Annahmen!$B$11) -> 2460 | I20: =I11*(Annahmen!$B$12/(1-Annahmen!$B$15*(1-I6))*Annahmen!$B$5+Annahmen!$B$13/(1-Annahmen!$B$15*(1-I6))*Annahmen!$B$8+Annahmen!$B$15*I6*Annahmen!$B$11) -> 2590 | ... Y20: =Y11*(Annahmen!$B$12/(1-Annahmen!$B$15*(1-Y6))*Annahmen!$B$5+Annahmen!$B$13/(1-Annahmen!$B$15*(1-Y6))*Annahmen!$B$8+Annahmen!$B$15*Y6*Annahmen!$B$11) -> 851.4231
A21: Umsatz | B21: =B19+B20 -> 1823 | C21: =C19+C20 -> 2402.6367 | D21: =D19+D20 -> 4792.227 | E21: =E19+E20 -> 5925.7167 | F21: =F19+F20 -> 7033.7241 | G21: =G19+G20 -> 8116.8524 | H21: =H19+H20 -> 9175.6896 | I21: =I19+I20 -> 10439.309 | ... Y21: =Y19+Y20 -> 15016.327
A22: Kosten | B22: =Annahmen!$B$42+Annahmen!$B$43+B7*Annahmen!$B$40 -> 355 | C22: =Annahmen!$B$42+Annahmen!$B$43+C7*Annahmen!$B$40 -> 355 | D22: =Annahmen!$B$42+Annahmen!$B$43+D7*Annahmen!$B$40 -> 355 | E22: =Annahmen!$B$42+Annahmen!$B$43+E7*Annahmen!$B$40 -> 355 | F22: =Annahmen!$B$42+Annahmen!$B$43+F7*Annahmen!$B$40 -> 355 | G22: =Annahmen!$B$42+Annahmen!$B$43+G7*Annahmen!$B$40 -> 355 | H22: =Annahmen!$B$42+Annahmen!$B$43+H7*Annahmen!$B$40 -> 355 | I22: =Annahmen!$B$42+Annahmen!$B$43+I7*Annahmen!$B$40 -> 355 | ... Y22: =Annahmen!$B$42+Annahmen!$B$43+Y7*Annahmen!$B$40 -> 355
A23: Ergebnis vor Steuern (= Einkommen Gründer) | B23: =B21-B22 -> 1468 | C23: =C21-C22 -> 2047.6367 | D23: =D21-D22 -> 4437.227 | E23: =E21-E22 -> 5570.7167 | F23: =F21-F22 -> 6678.7241 | G23: =G21-G22 -> 7761.8524 | H23: =H21-H22 -> 8820.6896 | I23: =I21-I22 -> 10084.309 | ... Y23: =Y21-Y22 -> 14661.327
A24: Kasse kumuliert | B24: =B23 -> 1468 | C24: =B24+C23 -> 3515.6367 | D24: =C24+D23 -> 7952.8636 | E24: =D24+E23 -> 13523.58 | F24: =E24+F23 -> 20202.304 | G24: =F24+G23 -> 27964.157 | H24: =G24+H23 -> 36784.846 | I24: =H24+I23 -> 46869.156 | J24: =I24+J23 -> 58050.858 | ... Y24: =X24+Y23 -> 268701.85
A25: Belegte Stunden | B25: =B9+B11*B8 -> 37.083333 | C25: =C9+C11*C8 -> 43.5 | D25: =D9+D11*D8 -> 86.8525 | E25: =E9+E11*E8 -> 99.394375 | F25: =F9+F11*F8 -> 111.64824 | G25: =G9+G11*G8 -> 123.62102 | H25: =H9+H11*H8 -> 135.31943 | I25: =I9+I11*I8 -> 141.70838 | ... Y25: =Y9+Y11*Y8 -> 170

Sheet Solo Konservativ auto
A1: Solo-Plan · Szenario Konservativ · automatisiert ab Kunde 5 (24 Monate ab Nov 2026)
A2: Abschlüsse = Minimum aus Vertriebstempo und freien Stunden. Kundenzahlen sind Erwartungswerte.
A4: Monat | B4: Nov 26 | C4: Dez 26 | D4: Jan 27 | E4: Feb 27 | F4: Mär 27 | G4: Apr 27 | H4: Mai 27 | I4: Jun 27 | J4: Jul 27 | K4: Aug 27 | L4: Sep 27 | M4: Okt 27 | N4: Nov 27 | O4: Dez 27 | P4: Jan 28 | Q4: Feb 28 | R4: Mär 28 | S4: Apr 28 | T4: Mai 28 | U4: Jun 28 | V4: Jul 28 | W4: Aug 28 | X4: Sep 28 | Y4: Okt 28
A5: Abschluss-Ziel (Vertrieb) | B5: =Annahmen!$B$48 -> 1 | C5: =Annahmen!$B$48 -> 1 | D5: =Annahmen!$B$49 -> 2 | E5: =Annahmen!$B$49 -> 2 | F5: =Annahmen!$B$49 -> 2 | G5: =Annahmen!$B$49 -> 2 | H5: =Annahmen!$B$49 -> 2 | I5: =Annahmen!$B$49 -> 2 | J5: =Annahmen!$B$49 -> 2 | K5: =Annahmen!$B$49 -> 2 | ... Y5: =Annahmen!$B$49 -> 2
A6: Recruiting im Verkauf (1 = ja) | B6: =IF(1>=Annahmen!$B$16,1,0) -> 0 | C6: =IF(2>=Annahmen!$B$16,1,0) -> 0 | D6: =IF(3>=Annahmen!$B$16,1,0) -> 0 | E6: =IF(4>=Annahmen!$B$16,1,0) -> 0 | F6: =IF(5>=Annahmen!$B$16,1,0) -> 0 | G6: =IF(6>=Annahmen!$B$16,1,0) -> 0 | H6: =IF(7>=Annahmen!$B$16,1,0) -> 0 | I6: =IF(8>=Annahmen!$B$16,1,0) -> 1 | J6: =IF(9>=Annahmen!$B$16,1,0) -> 1 | K6: =IF(10>=Annahmen!$B$16,1,0) -> 1 | L6: =IF(11>=Annahmen!$B$16,1,0) -> 1 | M6: =IF(12>=Annahmen!$B$16,1,0) -> 1 | N6: =IF(13>=Annahmen!$B$16,1,0) -> 1 | O6: =IF(14>=Annahmen!$B$16,1,0) -> 1 | P6: =IF(15>=Annahmen!$B$16,1,0) -> 1 | Q6: =IF(16>=Annahmen!$B$16,1,0) -> 1 | R6: =IF(17>=Annahmen!$B$16,1,0) -> 1 | S6: =IF(18>=Annahmen!$B$16,1,0) -> 1 | T6: =IF(19>=Annahmen!$B$16,1,0) -> 1 | U6: =IF(20>=Annahmen!$B$16,1,0) -> 1 | V6: =IF(21>=Annahmen!$B$16,1,0) -> 1 | W6: =IF(22>=Annahmen!$B$16,1,0) -> 1 | X6: =IF(23>=Annahmen!$B$16,1,0) -> 1 | Y6: =IF(24>=Annahmen!$B$16,1,0) -> 1
A7: Automatisierung aktiv (1 = ja) | B7: =IF(0>=Annahmen!$B$39-1,1,0) -> 0 | C7: =IF(B12>=Annahmen!$B$39-1,1,0) -> 0 | D7: =IF(C12>=Annahmen!$B$39-1,1,0) -> 0 | E7: =IF(D12>=Annahmen!$B$39-1,1,0) -> 1 | F7: =IF(E12>=Annahmen!$B$39-1,1,0) -> 1 | G7: =IF(F12>=Annahmen!$B$39-1,1,0) -> 1 | H7: =IF(G12>=Annahmen!$B$39-1,1,0) -> 1 | I7: =IF(H12>=Annahmen!$B$39-1,1,0) -> 1 | J7: =IF(I12>=Annahmen!$B$39-1,1,0) -> 1 | ... Y7: =IF(X12>=Annahmen!$B$39-1,1,0) -> 1
A8: Std. je neuem Abschluss | B8: =Annahmen!$B$12/(1-Annahmen!$B$15*(1-B6))*((Annahmen!$B$21+B7*(Annahmen!$B$30-Annahmen!$B$21))+(Annahmen!$B$25+B7*(Annahmen!$B$34-Annahmen!$B$25))+(Annahmen!$B$29+B7*(Annahmen!$B$38-Annahmen!$B$29)))+Annahmen!$B$13/(1-Annahmen!$B$15*(1-B6))*((Annahmen!$B$22+B7*(Annahmen!$B$31-Annahmen!$B$22))+(Annahmen!$B$26+B7*(Annahmen!$B$35-Annahmen!$B$26))+(Annahmen!$B$29+B7*(Annahmen!$B$38-Annahmen!$B$29)))+Annahmen!$B$14/(1-Annahmen!$B$15*(1-B6))*((Annahmen!$B$23+B7*(Annahmen!$B$32-Annahmen!$B$23))+(Annahmen!$B$27+B7*(Annahmen!$B$36-Annahmen!$B$27))+(Annahmen!$B$29+B7*(Annahmen!$B$38-Annahmen!$B$29)))+Annahmen!$B$15*B6*((Annahmen!$B$24+B7*(Annahmen!$B$33-Annahmen!$B$24))+(Annahmen!$B$28+B7*(Annahmen!$B$37-Annahmen!$B$28))+(Annahmen!$B$29+B7*(Annahmen!$B$38-Annahmen!$B$29))) -> 37.083333 | C8: =Annahmen!$B$12/(1-Annahmen!$B$15*(1-C6))*((Annahmen!$B$21+C7*(Annahmen!$B$30-Annahmen!$B$21))+(Annahmen!$B$25+C7*(Annahmen!$B$34-Annahmen!$B$25))+(Annahmen!$B$29+C7*(Annahmen!$B$38-Annahmen!$B$29)))+Annahmen!$B$13/(1-Annahmen!$B$15*(1-C6))*((Annahmen!$B$22+C7*(Annahmen!$B$31-Annahmen!$B$22))+(Annahmen!$B$26+C7*(Annahmen!$B$35-Annahmen!$B$26))+(Annahmen!$B$29+C7*(Annahmen!$B$38-Annahmen!$B$29)))+Annahmen!$B$14/(1-Annahmen!$B$15*(1-C6))*((Annahmen!$B$23+C7*(Annahmen!$B$32-Annahmen!$B$23))+(Annahmen!$B$27+C7*(Annahmen!$B$36-Annahmen!$B$27))+(Annahmen!$B$29+C7*(Annahmen!$B$38-Annahmen!$B$29)))+Annahmen!$B$15*C6*((Annahmen!$B$24+C7*(Annahmen!$B$33-Annahmen!$B$24))+(Annahmen!$B$28+C7*(Annahmen!$B$37-Annahmen!$B$28))+(Annahmen!$B$29+C7*(Annahmen!$B$38-Annahmen!$B$29))) -> 37.083333 | D8: =Annahmen!$B$12/(1-Annahmen!$B$15*(1-D6))*((Annahmen!$B$21+D7*(Annahmen!$B$30-Annahmen!$B$21))+(Annahmen!$B$25+D7*(Annahmen!$B$34-Annahmen!$B$25))+(Annahmen!$B$29+D7*(Annahmen!$B$38-Annahmen!$B$29)))+Annahmen!$B$13/(1-Annahmen!$B$15*(1-D6))*((Annahmen!$B$22+D7*(Annahmen!$B$31-Annahmen!$B$22))+(Annahmen!$B$26+D7*(Annahmen!$B$35-Annahmen!$B$26))+(Annahmen!$B$29+D7*(Annahmen!$B$38-Annahmen!$B$29)))+Annahmen!$B$14/(1-Annahmen!$B$15*(1-D6))*((Annahmen!$B$23+D7*(Annahmen!$B$32-Annahmen!$B$23))+(Annahmen!$B$27+D7*(Annahmen!$B$36-Annahmen!$B$27))+(Annahmen!$B$29+D7*(Annahmen!$B$38-Annahmen!$B$29)))+Annahmen!$B$15*D6*((Annahmen!$B$24+D7*(Annahmen!$B$33-Annahmen!$B$24))+(Annahmen!$B$28+D7*(Annahmen!$B$37-Annahmen!$B$28))+(Annahmen!$B$29+D7*(Annahmen!$B$38-Annahmen!$B$29))) -> 37.083333 | E8: =Annahmen!$B$12/(1-Annahmen!$B$15*(1-E6))*((Annahmen!$B$21+E7*(Annahmen!$B$30-Annahmen!$B$21))+(Annahmen!$B$25+E7*(Annahmen!$B$34-Annahmen!$B$25))+(Annahmen!$B$29+E7*(Annahmen!$B$38-Annahmen!$B$29)))+Annahmen!$B$13/(1-Annahmen!$B$15*(1-E6))*((Annahmen!$B$22+E7*(Annahmen!$B$31-Annahmen!$B$22))+(Annahmen!$B$26+E7*(Annahmen!$B$35-Annahmen!$B$26))+(Annahmen!$B$29+E7*(Annahmen!$B$38-Annahmen!$B$29)))+Annahmen!$B$14/(1-Annahmen!$B$15*(1-E6))*((Annahmen!$B$23+E7*(Annahmen!$B$32-Annahmen!$B$23))+(Annahmen!$B$27+E7*(Annahmen!$B$36-Annahmen!$B$27))+(Annahmen!$B$29+E7*(Annahmen!$B$38-Annahmen!$B$29)))+Annahmen!$B$15*E6*((Annahmen!$B$24+E7*(Annahmen!$B$33-Annahmen!$B$24))+(Annahmen!$B$28+E7*(Annahmen!$B$37-Annahmen!$B$28))+(Annahmen!$B$29+E7*(Annahmen!$B$38-Annahmen!$B$29))) -> 19.033333 | F8: =Annahmen!$B$12/(1-Annahmen!$B$15*(1-F6))*((Annahmen!$B$21+F7*(Annahmen!$B$30-Annahmen!$B$21))+(Annahmen!$B$25+F7*(Annahmen!$B$34-Annahmen!$B$25))+(Annahmen!$B$29+F7*(Annahmen!$B$38-Annahmen!$B$29)))+Annahmen!$B$13/(1-Annahmen!$B$15*(1-F6))*((Annahmen!$B$22+F7*(Annahmen!$B$31-Annahmen!$B$22))+(Annahmen!$B$26+F7*(Annahmen!$B$35-Annahmen!$B$26))+(Annahmen!$B$29+F7*(Annahmen!$B$38-Annahmen!$B$29)))+Annahmen!$B$14/(1-Annahmen!$B$15*(1-F6))*((Annahmen!$B$23+F7*(Annahmen!$B$32-Annahmen!$B$23))+(Annahmen!$B$27+F7*(Annahmen!$B$36-Annahmen!$B$27))+(Annahmen!$B$29+F7*(Annahmen!$B$38-Annahmen!$B$29)))+Annahmen!$B$15*F6*((Annahmen!$B$24+F7*(Annahmen!$B$33-Annahmen!$B$24))+(Annahmen!$B$28+F7*(Annahmen!$B$37-Annahmen!$B$28))+(Annahmen!$B$29+F7*(Annahmen!$B$38-Annahmen!$B$29))) -> 19.033333 | G8: =Annahmen!$B$12/(1-Annahmen!$B$15*(1-G6))*((Annahmen!$B$21+G7*(Annahmen!$B$30-Annahmen!$B$21))+(Annahmen!$B$25+G7*(Annahmen!$B$34-Annahmen!$B$25))+(Annahmen!$B$29+G7*(Annahmen!$B$38-Annahmen!$B$29)))+Annahmen!$B$13/(1-Annahmen!$B$15*(1-G6))*((Annahmen!$B$22+G7*(Annahmen!$B$31-Annahmen!$B$22))+(Annahmen!$B$26+G7*(Annahmen!$B$35-Annahmen!$B$26))+(Annahmen!$B$29+G7*(Annahmen!$B$38-Annahmen!$B$29)))+Annahmen!$B$14/(1-Annahmen!$B$15*(1-G6))*((Annahmen!$B$23+G7*(Annahmen!$B$32-Annahmen!$B$23))+(Annahmen!$B$27+G7*(Annahmen!$B$36-Annahmen!$B$27))+(Annahmen!$B$29+G7*(Annahmen!$B$38-Annahmen!$B$29)))+Annahmen!$B$15*G6*((Annahmen!$B$24+G7*(Annahmen!$B$33-Annahmen!$B$24))+(Annahmen!$B$28+G7*(Annahmen!$B$37-Annahmen!$B$28))+(Annahmen!$B$29+G7*(Annahmen!$B$38-Annahmen!$B$29))) -> 19.033333 | H8: =Annahmen!$B$12/(1-Annahmen!$B$15*(1-H6))*((Annahmen!$B$21+H7*(Annahmen!$B$30-Annahmen!$B$21))+(Annahmen!$B$25+H7*(Annahmen!$B$34-Annahmen!$B$25))+(Annahmen!$B$29+H7*(Annahmen!$B$38-Annahmen!$B$29)))+Annahmen!$B$13/(1-Annahmen!$B$15*(1-H6))*((Annahmen!$B$22+H7*(Annahmen!$B$31-Annahmen!$B$22))+(Annahmen!$B$26+H7*(Annahmen!$B$35-Annahmen!$B$26))+(Annahmen!$B$29+H7*(Annahmen!$B$38-Annahmen!$B$29)))+Annahmen!$B$14/(1-Annahmen!$B$15*(1-H6))*((Annahmen!$B$23+H7*(Annahmen!$B$32-Annahmen!$B$23))+(Annahmen!$B$27+H7*(Annahmen!$B$36-Annahmen!$B$27))+(Annahmen!$B$29+H7*(Annahmen!$B$38-Annahmen!$B$29)))+Annahmen!$B$15*H6*((Annahmen!$B$24+H7*(Annahmen!$B$33-Annahmen!$B$24))+(Annahmen!$B$28+H7*(Annahmen!$B$37-Annahmen!$B$28))+(Annahmen!$B$29+H7*(Annahmen!$B$38-Annahmen!$B$29))) -> 19.033333 | I8: =Annahmen!$B$12/(1-Annahmen!$B$15*(1-I6))*((Annahmen!$B$21+I7*(Annahmen!$B$30-Annahmen!$B$21))+(Annahmen!$B$25+I7*(Annahmen!$B$34-Annahmen!$B$25))+(Annahmen!$B$29+I7*(Annahmen!$B$38-Annahmen!$B$29)))+Annahmen!$B$13/(1-Annahmen!$B$15*(1-I6))*((Annahmen!$B$22+I7*(Annahmen!$B$31-Annahmen!$B$22))+(Annahmen!$B$26+I7*(Annahmen!$B$35-Annahmen!$B$26))+(Annahmen!$B$29+I7*(Annahmen!$B$38-Annahmen!$B$29)))+Annahmen!$B$14/(1-Annahmen!$B$15*(1-I6))*((Annahmen!$B$23+I7*(Annahmen!$B$32-Annahmen!$B$23))+(Annahmen!$B$27+I7*(Annahmen!$B$36-Annahmen!$B$27))+(Annahmen!$B$29+I7*(Annahmen!$B$38-Annahmen!$B$29)))+Annahmen!$B$15*I6*((Annahmen!$B$24+I7*(Annahmen!$B$33-Annahmen!$B$24))+(Annahmen!$B$28+I7*(Annahmen!$B$37-Annahmen!$B$28))+(Annahmen!$B$29+I7*(Annahmen!$B$38-Annahmen!$B$29))) -> 18.275 | ... Y8: =Annahmen!$B$12/(1-Annahmen!$B$15*(1-Y6))*((Annahmen!$B$21+Y7*(Annahmen!$B$30-Annahmen!$B$21))+(Annahmen!$B$25+Y7*(Annahmen!$B$34-Annahmen!$B$25))+(Annahmen!$B$29+Y7*(Annahmen!$B$38-Annahmen!$B$29)))+Annahmen!$B$13/(1-Annahmen!$B$15*(1-Y6))*((Annahmen!$B$22+Y7*(Annahmen!$B$31-Annahmen!$B$22))+(Annahmen!$B$26+Y7*(Annahmen!$B$35-Annahmen!$B$26))+(Annahmen!$B$29+Y7*(Annahmen!$B$38-Annahmen!$B$29)))+Annahmen!$B$14/(1-Annahmen!$B$15*(1-Y6))*((Annahmen!$B$23+Y7*(Annahmen!$B$32-Annahmen!$B$23))+(Annahmen!$B$27+Y7*(Annahmen!$B$36-Annahmen!$B$27))+(Annahmen!$B$29+Y7*(Annahmen!$B$38-Annahmen!$B$29)))+Annahmen!$B$15*Y6*((Annahmen!$B$24+Y7*(Annahmen!$B$33-Annahmen!$B$24))+(Annahmen!$B$28+Y7*(Annahmen!$B$37-Annahmen!$B$28))+(Annahmen!$B$29+Y7*(Annahmen!$B$38-Annahmen!$B$29))) -> 18.275
A9: Laufende Stunden (Bestand) | B9: =0*(Annahmen!$B$25+B7*(Annahmen!$B$34-Annahmen!$B$25))+0*(Annahmen!$B$26+B7*(Annahmen!$B$35-Annahmen!$B$26))+0*(Annahmen!$B$27+B7*(Annahmen!$B$36-Annahmen!$B$27))+0*(Annahmen!$B$28+B7*(Annahmen!$B$37-Annahmen!$B$28)) -> 0 | C9: =B14*(Annahmen!$B$25+C7*(Annahmen!$B$34-Annahmen!$B$25))+B15*(Annahmen!$B$26+C7*(Annahmen!$B$35-Annahmen!$B$26))+B16*(Annahmen!$B$27+C7*(Annahmen!$B$36-Annahmen!$B$27))+B17*(Annahmen!$B$28+C7*(Annahmen!$B$37-Annahmen!$B$28)) -> 6.4166667 | D9: =C14*(Annahmen!$B$25+D7*(Annahmen!$B$34-Annahmen!$B$25))+C15*(Annahmen!$B$26+D7*(Annahmen!$B$35-Annahmen!$B$26))+C16*(Annahmen!$B$27+D7*(Annahmen!$B$36-Annahmen!$B$27))+C17*(Annahmen!$B$28+D7*(Annahmen!$B$37-Annahmen!$B$28)) -> 12.685833 | E9: =D14*(Annahmen!$B$25+E7*(Annahmen!$B$34-Annahmen!$B$25))+D15*(Annahmen!$B$26+E7*(Annahmen!$B$35-Annahmen!$B$26))+D16*(Annahmen!$B$27+E7*(Annahmen!$B$36-Annahmen!$B$27))+D17*(Annahmen!$B$28+E7*(Annahmen!$B$37-Annahmen!$B$28)) -> 13.237503 | F9: =E14*(Annahmen!$B$25+F7*(Annahmen!$B$34-Annahmen!$B$25))+E15*(Annahmen!$B$26+F7*(Annahmen!$B$35-Annahmen!$B$26))+E16*(Annahmen!$B$27+F7*(Annahmen!$B$36-Annahmen!$B$27))+E17*(Annahmen!$B$28+F7*(Annahmen!$B$37-Annahmen!$B$28)) -> 19.668301 | G9: =F14*(Annahmen!$B$25+G7*(Annahmen!$B$34-Annahmen!$B$25))+F15*(Annahmen!$B$26+G7*(Annahmen!$B$35-Annahmen!$B$26))+F16*(Annahmen!$B$27+G7*(Annahmen!$B$36-Annahmen!$B$27))+F17*(Annahmen!$B$28+G7*(Annahmen!$B$37-Annahmen!$B$28)) -> 25.952309 | H9: =G14*(Annahmen!$B$25+H7*(Annahmen!$B$34-Annahmen!$B$25))+G15*(Annahmen!$B$26+H7*(Annahmen!$B$35-Annahmen!$B$26))+G16*(Annahmen!$B$27+H7*(Annahmen!$B$36-Annahmen!$B$27))+G17*(Annahmen!$B$28+H7*(Annahmen!$B$37-Annahmen!$B$28)) -> 32.093023 | I9: =H14*(Annahmen!$B$25+I7*(Annahmen!$B$34-Annahmen!$B$25))+H15*(Annahmen!$B$26+I7*(Annahmen!$B$35-Annahmen!$B$26))+H16*(Annahmen!$B$27+I7*(Annahmen!$B$36-Annahmen!$B$27))+H17*(Annahmen!$B$28+I7*(Annahmen!$B$37-Annahmen!$B$28)) -> 38.093848 | J9: =I14*(Annahmen!$B$25+J7*(Annahmen!$B$34-Annahmen!$B$25))+I15*(Annahmen!$B$26+J7*(Annahmen!$B$35-Annahmen!$B$26))+I16*(Annahmen!$B$27+J7*(Annahmen!$B$36-Annahmen!$B$27))+I17*(Annahmen!$B$28+J7*(Annahmen!$B$37-Annahmen!$B$28)) -> 44.274775 | ... Y9: =X14*(Annahmen!$B$25+Y7*(Annahmen!$B$34-Annahmen!$B$25))+X15*(Annahmen!$B$26+Y7*(Annahmen!$B$35-Annahmen!$B$26))+X16*(Annahmen!$B$27+Y7*(Annahmen!$B$36-Annahmen!$B$27))+X17*(Annahmen!$B$28+Y7*(Annahmen!$B$37-Annahmen!$B$28)) -> 117.16539
A10: Möglich nach Stunden | B10: =MAX(0,(Annahmen!$B$41-B9)/B8) -> 4.5842697 | C10: =MAX(0,(Annahmen!$B$41-C9)/C8) -> 4.411236 | D10: =MAX(0,(Annahmen!$B$41-D9)/D8) -> 4.2421798 | E10: =MAX(0,(Annahmen!$B$41-E9)/E8) -> 8.2362082 | F10: =MAX(0,(Annahmen!$B$41-F9)/F8) -> 7.898338 | G10: =MAX(0,(Annahmen!$B$41-G9)/G8) -> 7.5681799 | H10: =MAX(0,(Annahmen!$B$41-H9)/H8) -> 7.2455505 | I10: =MAX(0,(Annahmen!$B$41-I9)/I8) -> 7.2178469 | ... Y10: =MAX(0,(Annahmen!$B$41-Y9)/Y8) -> 2.8910866
A11: Abschlüsse | B11: =MIN(B5,B10) -> 1 | C11: =MIN(C5,C10) -> 1 | D11: =MIN(D5,D10) -> 2 | E11: =MIN(E5,E10) -> 2 | F11: =MIN(F5,F10) -> 2 | G11: =MIN(G5,G10) -> 2 | H11: =MIN(H5,H10) -> 2 | I11: =MIN(I5,I10) -> 2 | ... Y11: =MIN(Y5,Y10) -> 2
A12: Abschlüsse kumuliert | B12: =0+B11 -> 1 | C12: =B12+C11 -> 2 | D12: =C12+D11 -> 4 | E12: =D12+E11 -> 6 | F12: =E12+F11 -> 8 | G12: =F12+G11 -> 10 | H12: =G12+H11 -> 12 | I12: =H12+I11 -> 14 | J12: =I12+J11 -> 16 | ... Y12: =X12+Y11 -> 46
A14: Aktive Pflege-Kunden | B14: =0*(1-Annahmen!$B$17)+B11*Annahmen!$B$12/(1-Annahmen!$B$15*(1-B6)) -> 0.33333333 | C14: =B14*(1-Annahmen!$B$17)+C11*Annahmen!$B$12/(1-Annahmen!$B$15*(1-C6)) -> 0.66333333 | D14: =C14*(1-Annahmen!$B$17)+D11*Annahmen!$B$12/(1-Annahmen!$B$15*(1-D6)) -> 1.3233667 | E14: =D14*(1-Annahmen!$B$17)+E11*Annahmen!$B$12/(1-Annahmen!$B$15*(1-E6)) -> 1.9767997 | F14: =E14*(1-Annahmen!$B$17)+F11*Annahmen!$B$12/(1-Annahmen!$B$15*(1-F6)) -> 2.6236983 | G14: =F14*(1-Annahmen!$B$17)+G11*Annahmen!$B$12/(1-Annahmen!$B$15*(1-G6)) -> 3.264128 | H14: =G14*(1-Annahmen!$B$17)+H11*Annahmen!$B$12/(1-Annahmen!$B$15*(1-H6)) -> 3.8981534 | I14: =H14*(1-Annahmen!$B$17)+I11*Annahmen!$B$12/(1-Annahmen!$B$15*(1-I6)) -> 4.3591719 | J14: =I14*(1-Annahmen!$B$17)+J11*Annahmen!$B$12/(1-Annahmen!$B$15*(1-J6)) -> 4.8155802 | ... Y14: =X14*(1-Annahmen!$B$17)+Y11*Annahmen!$B$12/(1-Annahmen!$B$15*(1-Y6)) -> 11.138762
A15: Aktive Programm-Kunden | B15: =0*(1-Annahmen!$B$18)+B11*Annahmen!$B$13/(1-Annahmen!$B$15*(1-B6)) -> 0.33333333 | C15: =B15*(1-Annahmen!$B$18)+C11*Annahmen!$B$13/(1-Annahmen!$B$15*(1-C6)) -> 0.66 | D15: =C15*(1-Annahmen!$B$18)+D11*Annahmen!$B$13/(1-Annahmen!$B$15*(1-D6)) -> 1.3134667 | E15: =D15*(1-Annahmen!$B$18)+E11*Annahmen!$B$13/(1-Annahmen!$B$15*(1-E6)) -> 1.953864 | F15: =E15*(1-Annahmen!$B$18)+F11*Annahmen!$B$13/(1-Annahmen!$B$15*(1-F6)) -> 2.5814534 | G15: =F15*(1-Annahmen!$B$18)+G11*Annahmen!$B$13/(1-Annahmen!$B$15*(1-G6)) -> 3.196491 | H15: =G15*(1-Annahmen!$B$18)+H11*Annahmen!$B$13/(1-Annahmen!$B$15*(1-H6)) -> 3.7992278 | I15: =H15*(1-Annahmen!$B$18)+I11*Annahmen!$B$13/(1-Annahmen!$B$15*(1-I6)) -> 4.2232433 | J15: =I15*(1-Annahmen!$B$18)+J11*Annahmen!$B$13/(1-Annahmen!$B$15*(1-J6)) -> 4.6387784 | ... Y15: =X15*(1-Annahmen!$B$18)+Y11*Annahmen!$B$13/(1-Annahmen!$B$15*(1-Y6)) -> 9.9618308
A16: Aktive SEO-Kunden | B16: =0*(1-Annahmen!$B$19)+B11*Annahmen!$B$14/(1-Annahmen!$B$15*(1-B6)) -> 0.33333333 | C16: =B16*(1-Annahmen!$B$19)+C11*Annahmen!$B$14/(1-Annahmen!$B$15*(1-C6)) -> 0.65666667 | D16: =C16*(1-Annahmen!$B$19)+D11*Annahmen!$B$14/(1-Annahmen!$B$15*(1-D6)) -> 1.3036333 | E16: =D16*(1-Annahmen!$B$19)+E11*Annahmen!$B$14/(1-Annahmen!$B$15*(1-E6)) -> 1.931191 | F16: =E16*(1-Annahmen!$B$19)+F11*Annahmen!$B$14/(1-Annahmen!$B$15*(1-F6)) -> 2.5399219 | G16: =F16*(1-Annahmen!$B$19)+G11*Annahmen!$B$14/(1-Annahmen!$B$15*(1-G6)) -> 3.1303909 | H16: =G16*(1-Annahmen!$B$19)+H11*Annahmen!$B$14/(1-Annahmen!$B$15*(1-H6)) -> 3.7031459 | I16: =H16*(1-Annahmen!$B$19)+I11*Annahmen!$B$14/(1-Annahmen!$B$15*(1-I6)) -> 4.0920515 | J16: =I16*(1-Annahmen!$B$19)+J11*Annahmen!$B$14/(1-Annahmen!$B$15*(1-J6)) -> 4.46929 | ... Y16: =X16*(1-Annahmen!$B$19)+Y11*Annahmen!$B$14/(1-Annahmen!$B$15*(1-Y6)) -> 8.9426634
A17: Aktive Recruiting-Kunden | B17: =0*(1-Annahmen!$B$20)+B11*Annahmen!$B$15*B6 -> 0 | C17: =B17*(1-Annahmen!$B$20)+C11*Annahmen!$B$15*C6 -> 0 | D17: =C17*(1-Annahmen!$B$20)+D11*Annahmen!$B$15*D6 -> 0 | E17: =D17*(1-Annahmen!$B$20)+E11*Annahmen!$B$15*E6 -> 0 | F17: =E17*(1-Annahmen!$B$20)+F11*Annahmen!$B$15*F6 -> 0 | G17: =F17*(1-Annahmen!$B$20)+G11*Annahmen!$B$15*G6 -> 0 | H17: =G17*(1-Annahmen!$B$20)+H11*Annahmen!$B$15*H6 -> 0 | I17: =H17*(1-Annahmen!$B$20)+I11*Annahmen!$B$15*I6 -> 0.5 | J17: =I17*(1-Annahmen!$B$20)+J11*Annahmen!$B$15*J6 -> 0.975 | ... Y17: =X17*(1-Annahmen!$B$20)+Y11*Annahmen!$B$15*Y6 -> 5.8187966
A19: MRR | B19: =B14*Annahmen!$B$6+B15*Annahmen!$B$7+B16*Annahmen!$B$9+B17*Annahmen!$B$10 -> 593 | C19: =C14*Annahmen!$B$6+C15*Annahmen!$B$7+C16*Annahmen!$B$9+C17*Annahmen!$B$10 -> 1172.6367 | D19: =D14*Annahmen!$B$6+D15*Annahmen!$B$7+D16*Annahmen!$B$9+D17*Annahmen!$B$10 -> 2332.227 | E19: =E14*Annahmen!$B$6+E15*Annahmen!$B$7+E16*Annahmen!$B$9+E17*Annahmen!$B$10 -> 3465.7167 | F19: =F14*Annahmen!$B$6+F15*Annahmen!$B$7+F16*Annahmen!$B$9+F17*Annahmen!$B$10 -> 4573.7241 | G19: =G14*Annahmen!$B$6+G15*Annahmen!$B$7+G16*Annahmen!$B$9+G17*Annahmen!$B$10 -> 5656.8524 | H19: =H14*Annahmen!$B$6+H15*Annahmen!$B$7+H16*Annahmen!$B$9+H17*Annahmen!$B$10 -> 6715.6896 | I19: =I14*Annahmen!$B$6+I15*Annahmen!$B$7+I16*Annahmen!$B$9+I17*Annahmen!$B$10 -> 7849.3091 | ... Y19: =Y14*Annahmen!$B$6+Y15*Annahmen!$B$7+Y16*Annahmen!$B$9+Y17*Annahmen!$B$10 -> 21870.188
A20: Einmalumsatz | B20: =B11*(Annahmen!$B$12/(1-Annahmen!$B$15*(1-B6))*Annahmen!$B$5+Annahmen!$B$13/(1-Annahmen!$B$15*(1-B6))*Annahmen!$B$8+Annahmen!$B$15*B6*Annahmen!$B$11) -> 1230 | C20: =C11*(Annahmen!$B$12/(1-Annahmen!$B$15*(1-C6))*Annahmen!$B$5+Annahmen!$B$13/(1-Annahmen!$B$15*(1-C6))*Annahmen!$B$8+Annahmen!$B$15*C6*Annahmen!$B$11) -> 1230 | D20: =D11*(Annahmen!$B$12/(1-Annahmen!$B$15*(1-D6))*Annahmen!$B$5+Annahmen!$B$13/(1-Annahmen!$B$15*(1-D6))*Annahmen!$B$8+Annahmen!$B$15*D6*Annahmen!$B$11) -> 2460 | E20: =E11*(Annahmen!$B$12/(1-Annahmen!$B$15*(1-E6))*Annahmen!$B$5+Annahmen!$B$13/(1-Annahmen!$B$15*(1-E6))*Annahmen!$B$8+Annahmen!$B$15*E6*Annahmen!$B$11) -> 2460 | F20: =F11*(Annahmen!$B$12/(1-Annahmen!$B$15*(1-F6))*Annahmen!$B$5+Annahmen!$B$13/(1-Annahmen!$B$15*(1-F6))*Annahmen!$B$8+Annahmen!$B$15*F6*Annahmen!$B$11) -> 2460 | G20: =G11*(Annahmen!$B$12/(1-Annahmen!$B$15*(1-G6))*Annahmen!$B$5+Annahmen!$B$13/(1-Annahmen!$B$15*(1-G6))*Annahmen!$B$8+Annahmen!$B$15*G6*Annahmen!$B$11) -> 2460 | H20: =H11*(Annahmen!$B$12/(1-Annahmen!$B$15*(1-H6))*Annahmen!$B$5+Annahmen!$B$13/(1-Annahmen!$B$15*(1-H6))*Annahmen!$B$8+Annahmen!$B$15*H6*Annahmen!$B$11) -> 2460 | I20: =I11*(Annahmen!$B$12/(1-Annahmen!$B$15*(1-I6))*Annahmen!$B$5+Annahmen!$B$13/(1-Annahmen!$B$15*(1-I6))*Annahmen!$B$8+Annahmen!$B$15*I6*Annahmen!$B$11) -> 2590 | ... Y20: =Y11*(Annahmen!$B$12/(1-Annahmen!$B$15*(1-Y6))*Annahmen!$B$5+Annahmen!$B$13/(1-Annahmen!$B$15*(1-Y6))*Annahmen!$B$8+Annahmen!$B$15*Y6*Annahmen!$B$11) -> 2590
A21: Umsatz | B21: =B19+B20 -> 1823 | C21: =C19+C20 -> 2402.6367 | D21: =D19+D20 -> 4792.227 | E21: =E19+E20 -> 5925.7167 | F21: =F19+F20 -> 7033.7241 | G21: =G19+G20 -> 8116.8524 | H21: =H19+H20 -> 9175.6896 | I21: =I19+I20 -> 10439.309 | ... Y21: =Y19+Y20 -> 24460.188
A22: Kosten | B22: =Annahmen!$B$42+Annahmen!$B$43+B7*Annahmen!$B$40 -> 355 | C22: =Annahmen!$B$42+Annahmen!$B$43+C7*Annahmen!$B$40 -> 355 | D22: =Annahmen!$B$42+Annahmen!$B$43+D7*Annahmen!$B$40 -> 355 | E22: =Annahmen!$B$42+Annahmen!$B$43+E7*Annahmen!$B$40 -> 505 | F22: =Annahmen!$B$42+Annahmen!$B$43+F7*Annahmen!$B$40 -> 505 | G22: =Annahmen!$B$42+Annahmen!$B$43+G7*Annahmen!$B$40 -> 505 | H22: =Annahmen!$B$42+Annahmen!$B$43+H7*Annahmen!$B$40 -> 505 | I22: =Annahmen!$B$42+Annahmen!$B$43+I7*Annahmen!$B$40 -> 505 | ... Y22: =Annahmen!$B$42+Annahmen!$B$43+Y7*Annahmen!$B$40 -> 505
A23: Ergebnis vor Steuern (= Einkommen Gründer) | B23: =B21-B22 -> 1468 | C23: =C21-C22 -> 2047.6367 | D23: =D21-D22 -> 4437.227 | E23: =E21-E22 -> 5420.7167 | F23: =F21-F22 -> 6528.7241 | G23: =G21-G22 -> 7611.8524 | H23: =H21-H22 -> 8670.6896 | I23: =I21-I22 -> 9934.3091 | ... Y23: =Y21-Y22 -> 23955.188
A24: Kasse kumuliert | B24: =B23 -> 1468 | C24: =B24+C23 -> 3515.6367 | D24: =C24+D23 -> 7952.8636 | E24: =D24+E23 -> 13373.58 | F24: =E24+F23 -> 19902.304 | G24: =F24+G23 -> 27514.157 | H24: =G24+H23 -> 36184.846 | I24: =H24+I23 -> 46119.156 | J24: =I24+J23 -> 57150.858 | ... Y24: =X24+Y23 -> 333427.31
A25: Belegte Stunden | B25: =B9+B11*B8 -> 37.083333 | C25: =C9+C11*C8 -> 43.5 | D25: =D9+D11*D8 -> 86.8525 | E25: =E9+E11*E8 -> 51.30417 | F25: =F9+F11*F8 -> 57.734968 | G25: =G9+G11*G8 -> 64.018976 | H25: =H9+H11*H8 -> 70.159689 | I25: =I9+I11*I8 -> 74.643848 | ... Y25: =Y9+Y11*Y8 -> 153.71539

Sheet Solo Basis
A1: Solo-Plan · Szenario Basis · von Hand (24 Monate ab Nov 2026)
A2: Abschlüsse = Minimum aus Vertriebstempo und freien Stunden. Kundenzahlen sind Erwartungswerte.
A4: Monat | B4: Nov 26 | C4: Dez 26 | D4: Jan 27 | E4: Feb 27 | F4: Mär 27 | G4: Apr 27 | H4: Mai 27 | I4: Jun 27 | J4: Jul 27 | K4: Aug 27 | L4: Sep 27 | M4: Okt 27 | N4: Nov 27 | O4: Dez 27 | P4: Jan 28 | Q4: Feb 28 | R4: Mär 28 | S4: Apr 28 | T4: Mai 28 | U4: Jun 28 | V4: Jul 28 | W4: Aug 28 | X4: Sep 28 | Y4: Okt 28
A5: Abschluss-Ziel (Vertrieb) | B5: =Annahmen!$C$48 -> 2 | C5: =Annahmen!$C$48 -> 2 | D5: =Annahmen!$C$49 -> 3 | E5: =Annahmen!$C$49 -> 3 | F5: =Annahmen!$C$49 -> 3 | G5: =Annahmen!$C$49 -> 3 | H5: =Annahmen!$C$49 -> 3 | I5: =Annahmen!$C$49 -> 3 | J5: =Annahmen!$C$49 -> 3 | K5: =Annahmen!$C$49 -> 3 | ... Y5: =Annahmen!$C$49 -> 3
A6: Recruiting im Verkauf (1 = ja) | B6: =IF(1>=Annahmen!$B$16,1,0) -> 0 | C6: =IF(2>=Annahmen!$B$16,1,0) -> 0 | D6: =IF(3>=Annahmen!$B$16,1,0) -> 0 | E6: =IF(4>=Annahmen!$B$16,1,0) -> 0 | F6: =IF(5>=Annahmen!$B$16,1,0) -> 0 | G6: =IF(6>=Annahmen!$B$16,1,0) -> 0 | H6: =IF(7>=Annahmen!$B$16,1,0) -> 0 | I6: =IF(8>=Annahmen!$B$16,1,0) -> 1 | J6: =IF(9>=Annahmen!$B$16,1,0) -> 1 | K6: =IF(10>=Annahmen!$B$16,1,0) -> 1 | L6: =IF(11>=Annahmen!$B$16,1,0) -> 1 | M6: =IF(12>=Annahmen!$B$16,1,0) -> 1 | N6: =IF(13>=Annahmen!$B$16,1,0) -> 1 | O6: =IF(14>=Annahmen!$B$16,1,0) -> 1 | P6: =IF(15>=Annahmen!$B$16,1,0) -> 1 | Q6: =IF(16>=Annahmen!$B$16,1,0) -> 1 | R6: =IF(17>=Annahmen!$B$16,1,0) -> 1 | S6: =IF(18>=Annahmen!$B$16,1,0) -> 1 | T6: =IF(19>=Annahmen!$B$16,1,0) -> 1 | U6: =IF(20>=Annahmen!$B$16,1,0) -> 1 | V6: =IF(21>=Annahmen!$B$16,1,0) -> 1 | W6: =IF(22>=Annahmen!$B$16,1,0) -> 1 | X6: =IF(23>=Annahmen!$B$16,1,0) -> 1 | Y6: =IF(24>=Annahmen!$B$16,1,0) -> 1
A7: Automatisierung aktiv (1 = ja) | B7: =0 -> 0 | C7: =0 -> 0 | D7: =0 -> 0 | E7: =0 -> 0 | F7: =0 -> 0 | G7: =0 -> 0 | H7: =0 -> 0 | I7: =0 -> 0 | ... Y7: =0 -> 0
